# 에러 처리

## 에러 처리의 필요성

-   에러는 언제 발생 가능
-   발생한 에러를 방치하면 프로그램은 강제 종료된다

    ```js
    console.log('[Start]');

    foo(); // ReferenceError: foo is not defined

    console.log('[End]');
    ```

-   try ... catch 문을 사용하면 프로그램이 강제 종료되지 않고 코드를 실행시킬 수 있다

    ```js
    console.log('[Start]');

    try {
        foo();
    } catch (error) {
        console.error('[에러 발생]', error);
    }

    console.log('[End]');
    ```

-   직접적인 에러를 발생하지는 않는 예외적인 상황이 발생할 수도 있다

    ```ts
    // users.service.ts

    const findUser = await this.userDAO.getUserByEmail(
        // 직접적인 에러 발생하지 않음
        poolConnection!,
        user.email
    );
    if (!findUser) {
        await this.userDAO.createUser(poolConnection!, newUser); // user가 존재하지 않으면 에러 발생
    } else {
        throw new HttpException(409, '이미 존재하는 계정입니다.'); // 예외적인 상황에 대응하도록 에러 던지기
    }
    ```

## try ... catch ... finally 문

-   에러 처리하는 방법 중 하나
-   finally 문은 불필요하다면 생략 가능

    ```js
    console.log('[Start]');

    try {
        // 실행할 코드(에러 발생 가능성 있음)
        foo();
    } catch (error) {
        // try 코드 블록에서 에러가 발생하면 이 코드 블록의 코드가 실행된다
        // err에는 try 코드 블록에서 발생한 Error 객체가 전달된다
        console.error('[에러 발생]', error);
    }.finally {
        // 에러 발생과 상관없이 반드시 한 번 실행된다
        console.log('finally');
    }

    // try ... catch ... finally 문으로 에러를 처리하면 프로그램이 강제 종료되지 않는다
    console.log('[End]');
    ```

    ## Error 객체

    -   Error 생성자 함수는 에러 객체를 생성한다
    -   에러 메시지를 인수로 전달 가능

    ### Error 생성자 함수의 종류

    | 생성자 함수    | 인스턴스                                                                       |
    | -------------- | ------------------------------------------------------------------------------ |
    | Error          | 일반적 에러 객체                                                               |
    | SyntaxError    | 자바스크립트 문법에 맞지 않는 문을 해석할 때 발생하는 에러 객체                |
    | ReferenceError | 참조할 수 없는 식별자를 참조했을 때 발생하는 에러 객체                         |
    | TypeError      | 피연산자 또는 인수의 데이터 타입이 유효하지 않을 때 발생하는 에러 객체         |
    | RangeError     | 숫자값의 허용 범위를 벗어났을 때 발생하는 에러 객체                            |
    | URIError       | encodeURI 또는 decodeURI 함수에 부적절한 인수를 전달했을 때 발생하는 에러 객체 |
    | EvalError      | eval 함수에서 발생하는 에러 객체                                               |

    #### CustomError 객체

    ```ts
    export default class HttpException extends Error {
        public status: number;
        public message: string;

        constructor(status: number, message: string) {
            super(message);
            this.name = 'HttpException';
            this.status = status;
            this.message = message;
        }
    }
    ```

## throw 문

-   try 코드 블록에서 throw 문으로 에러 객체를 던지면, 코드 블록의 실행이 중단되고 가장 가까운 catch 문을 찾는다
-   catch 문을 찾지 못하면, 프로그램은 에러로 종료될 수 있다
-   catch 문을 찾는다면, 에러 변수가 생성되고 던져진 에러 객체가 할당된다
-   그 후, catch 코드 블록이 실행된다

    ```ts
    try {
        const { poolConnection } = req;
        const findUser = await this.userDAO.getUserByEmail(
            poolConnection!,
            user.email
        );
        if (!findUser) {
            await this.userDAO.createUser(poolConnection!, newUser);
        } else {
            throw new HttpException(409, '이미 존재하는 계정입니다.');
        }
    } catch (err) {
        // 던져진 HttpException 에러 객체가 할당된다
        next(err);
    }
    ```

## 에러의 전파

-   에러는 콜 스택의 아래 방향으로 전파된다
-   throw 된 에러를 캐치하지 않으면 프로그램은 강제 종료된다

![image](https://github.com/namu56/note-editor/assets/107787137/0231a8ae-faf8-41a8-88d9-e571639afc7d)
